#VRML_SIM R2023b utf8

EXTERNPROTO "https://raw.githubusercontent.com/cyberbotics/webots/R2023b/projects/appearances/protos/BrushedSteel.proto"
EXTERNPROTO "https://raw.githubusercontent.com/cyberbotics/webots/R2023b/projects/appearances/protos/Copper.proto"
EXTERNPROTO "https://raw.githubusercontent.com/cyberbotics/webots/R2023b/projects/appearances/protos/DamascusSteel.proto"
EXTERNPROTO "https://raw.githubusercontent.com/cyberbotics/webots/R2023b/projects/appearances/protos/HammeredCopper.proto"
EXTERNPROTO "https://raw.githubusercontent.com/cyberbotics/webots/R2023b/projects/appearances/protos/SandyGround.proto"
EXTERNPROTO "https://raw.githubusercontent.com/cyberbotics/webots/R2023b/projects/objects/backgrounds/protos/TexturedBackground.proto"
EXTERNPROTO "https://raw.githubusercontent.com/cyberbotics/webots/R2023b/projects/objects/backgrounds/protos/TexturedBackgroundLight.proto"
EXTERNPROTO "https://raw.githubusercontent.com/cyberbotics/webots/R2023b/projects/objects/floors/protos/UnevenTerrain.proto"
EXTERNPROTO "https://raw.githubusercontent.com/cyberbotics/webots/R2023b/projects/appearances/protos/SolarCell.proto"

WorldInfo {
  gravity 3.721
}
Viewpoint {
  orientation 0.02396941357720984 -0.014059874943287563 0.9996138189967884 3.151858413713268
  position 1.5961220682041408 0.1943357439357461 3.527893646637732
}
TexturedBackground {
  texture "mars"
}
TexturedBackgroundLight {
  luminosity 2
}
UnevenTerrain {
  appearance SandyGround {
    colorOverride 0.5 0.5 0.4
    textureTransform TextureTransform {
      scale 50 50
    }
  }
}
Robot {
  translation -0.8989156355925044 0.06604496023885557 3.3476500441547548
  rotation 0.705670173334921 -0.3225912021852632 -0.630844293576576 0.10526023479086039
  children [
    Shape {
      appearance SolarCell {
      }
      geometry Box {
        size 0.7 0.5 0.2
      }
    }
    Solid {
      translation -0.18 0.24 0
      rotation 0 0 1 3.14159
      children [
        SliderJoint {
          jointParameters JointParameters {
            position -1.4150539385051162e-05
            minStop -0.1
            staticFriction 1
          }
          device [
            LinearMotor {
              name "linear1_left"
              maxForce 50
            }
          ]
          endPoint Solid {
            translation -0.00017963410624999288 -0.017340974899748285 0.06004154266601735
            rotation 0.9999999928677722 -8.072942609765395e-05 8.801826542176677e-05 -1.5708554838577085
            children [
              DEF cylinder1 Shape {
                appearance DamascusSteel {
                }
                geometry Cylinder {
                  height 0.09
                  radius 0.02
                }
              }
              Solid {
                translation 0 0 -0.05
                children [
                  DEF sphere1 Shape {
                    appearance BrushedSteel {
                    }
                    geometry Sphere {
                      radius 0.02
                    }
                  }
                  Solid {
                    translation 0 0.1 1.79608e-07
                    rotation -1 0 0 -1.5707953071795862
                    children [
                      DEF cylinder2 Shape {
                        appearance BrushedSteel {
                        }
                        geometry Cylinder {
                          height 0.2
                          radius 0.02
                        }
                      }
                      Solid {
                        translation 0 0 -0.11
                        children [
                          DEF sphere1 Shape {
                            appearance BrushedSteel {
                            }
                            geometry Sphere {
                              radius 0.02
                            }
                          }
                          Solid {
                            translation 0 -0.03 -9.99999e-08
                            rotation 1 0 0 1.5708
                            children [
                              DEF cylinder3 Shape {
                                appearance BrushedSteel {
                                }
                                geometry Cylinder {
                                  height 0.06
                                  radius 0.02
                                }
                              }
                              HingeJoint {
                                jointParameters HingeJointParameters {
                                  position -4.627712123438957
                                  axis 0 0 1
                                  anchor -9.51224e-05 0.00113507 0.0800056
                                }
                                device [
                                  RotationalMotor {
                                    name "wheel1_left"
                                  }
                                ]
                                endPoint Solid {
                                  translation 0.0010015485188185121 0.001550873906594836 0.0800641
                                  rotation -4.813969433749166e-07 8.292271455099385e-07 0.9999999999995403 1.655477082801348
                                  children [
                                    DEF wheel Shape {
                                      appearance DamascusSteel {
                                      }
                                      geometry Cylinder {
                                        height 0.15
                                        radius 0.15
                                      }
                                    }
                                  ]
                                  boundingObject USE wheel
                                  physics Physics {
                                    mass 1
                                  }
                                  linearVelocity 0.00019176811087772902 0.0009713824917290584 -0.0041921976798206095
                                  angularVelocity -0.004443141629420229 0.0002956289585794485 -0.0001469060881784457
                                }
                              }
                            ]
                            boundingObject USE cylinder3
                            physics DEF phy1 Physics {
                              mass 1
                            }
                          }
                        ]
                        name "solid(1)"
                        boundingObject USE sphere1
                        physics USE phy1
                      }
                    ]
                    boundingObject USE cylinder2
                    physics USE phy1
                  }
                ]
                boundingObject USE sphere1
                physics USE phy1
              }
            ]
            boundingObject USE cylinder1
            physics USE phy1
            linearVelocity 0.00019291284252845298 0.0013999154602659118 -0.0037301743200243835
            angularVelocity -0.004444632245304014 0.0002905185074811604 -0.0001473620573511753
          }
        }
      ]
      name "wheel1_right_system"
      physics USE phy1
    }
    Solid {
      translation 0.18 0.24 0
      rotation 0 0 1 3.14159
      children [
        SliderJoint {
          jointParameters JointParameters {
            position -0.0006432513941544247
            minStop -0.1
            staticFriction 1
          }
          device [
            LinearMotor {
              name "linear1_left"
              maxForce 50
            }
          ]
          endPoint Solid {
            translation -0.00017985453301283538 -0.017342787906382884 0.05940803407645815
            rotation -0.9999999928695749 8.057119204137451e-05 -8.814268504930294e-05 1.5708453179831379
            children [
              DEF cylinder1 Shape {
                appearance DamascusSteel {
                }
                geometry Cylinder {
                  height 0.09
                  radius 0.02
                }
              }
              Solid {
                translation 0 0 -0.05
                children [
                  DEF sphere1 Shape {
                    appearance BrushedSteel {
                    }
                    geometry Sphere {
                      radius 0.02
                    }
                  }
                  Solid {
                    translation 0 0.1 1.79608e-07
                    rotation -1 0 0 -1.5707953071795862
                    children [
                      DEF cylinder2 Shape {
                        appearance BrushedSteel {
                        }
                        geometry Cylinder {
                          height 0.2
                          radius 0.02
                        }
                      }
                      Solid {
                        translation 0 0 -0.11
                        children [
                          DEF sphere1 Shape {
                            appearance BrushedSteel {
                            }
                            geometry Sphere {
                              radius 0.02
                            }
                          }
                          Solid {
                            translation 0 -0.03 -9.99999e-08
                            rotation 1 0 0 1.5708
                            children [
                              DEF cylinder3 Shape {
                                appearance BrushedSteel {
                                }
                                geometry Cylinder {
                                  height 0.06
                                  radius 0.02
                                }
                              }
                              HingeJoint {
                                jointParameters HingeJointParameters {
                                  position -4.627710488158102
                                  axis 0 0 1
                                  anchor -9.51224e-05 0.00113507 0.0800056
                                }
                                device [
                                  RotationalMotor {
                                    name "wheel1_left"
                                  }
                                ]
                                endPoint Solid {
                                  translation 0.0010015478388608772 0.0015508756999592366 0.0800641
                                  rotation -4.812231875939113e-07 8.289262826848459e-07 0.9999999999995407 1.6554787166723102
                                  children [
                                    DEF wheel Shape {
                                      appearance DamascusSteel {
                                      }
                                      geometry Cylinder {
                                        height 0.15
                                        radius 0.15
                                      }
                                    }
                                  ]
                                  boundingObject USE wheel
                                  physics Physics {
                                    mass 1
                                  }
                                  linearVelocity -0.0001637882420389761 0.00027107508917883653 0.005004828806866856
                                  angularVelocity -0.004486256062447743 0.00029516927410657215 -0.00014634722991324145
                                }
                              }
                            ]
                            boundingObject USE cylinder3
                            physics DEF phy1 Physics {
                              mass 1
                            }
                          }
                        ]
                        name "solid(1)"
                        boundingObject USE sphere1
                        physics USE phy1
                      }
                    ]
                    boundingObject USE cylinder2
                    physics USE phy1
                  }
                ]
                boundingObject USE sphere1
                physics USE phy1
              }
            ]
            boundingObject USE cylinder1
            physics USE phy1
            linearVelocity -0.00015531605387576145 0.0007007897562961237 0.005637495404136323
            angularVelocity -0.004485841491756697 0.00029593338643799875 -0.0001458385381187411
          }
        }
      ]
      name "wheel2_right_system"
      physics USE phy1
    }
    Solid {
      translation 0.18 -0.24 0
      children [
        SliderJoint {
          jointParameters JointParameters {
            position -1.2278072321895007e-05
            minStop -0.1
            staticFriction 1
          }
          device [
            LinearMotor {
              name "linear1_left"
              maxForce 50
            }
          ]
          endPoint Solid {
            translation -0.0001888577972838923 -0.01731429599078596 0.060037821723060984
            rotation -0.9999999931510345 8.067175650429466e-05 -8.479386030531768e-05 1.570845645370177
            children [
              DEF cylinder1 Shape {
                appearance DamascusSteel {
                }
                geometry Cylinder {
                  height 0.09
                  radius 0.02
                }
              }
              Solid {
                translation 0 0 -0.05
                children [
                  DEF sphere1 Shape {
                    appearance BrushedSteel {
                    }
                    geometry Sphere {
                      radius 0.02
                    }
                  }
                  Solid {
                    translation 0 0.1 1.79608e-07
                    rotation -1 0 0 -1.5707953071795862
                    children [
                      DEF cylinder2 Shape {
                        appearance BrushedSteel {
                        }
                        geometry Cylinder {
                          height 0.2
                          radius 0.02
                        }
                      }
                      Solid {
                        translation 0 0 -0.11
                        children [
                          DEF sphere1 Shape {
                            appearance BrushedSteel {
                            }
                            geometry Sphere {
                              radius 0.02
                            }
                          }
                          Solid {
                            translation 0 -0.03 -9.99999e-08
                            rotation 1 0 0 1.5708
                            children [
                              DEF cylinder3 Shape {
                                appearance BrushedSteel {
                                }
                                geometry Cylinder {
                                  height 0.06
                                  radius 0.02
                                }
                              }
                              HingeJoint {
                                jointParameters HingeJointParameters {
                                  position -4.627710794313752
                                  axis 0 0 1
                                  anchor -9.51224e-05 0.00113507 0.0800056
                                }
                                device [
                                  RotationalMotor {
                                    name "wheel1_left"
                                  }
                                ]
                                endPoint Solid {
                                  translation 0.0010015479661620915 0.0015508753642074265 0.0800641
                                  rotation -4.809992289723529e-07 8.285407970597212e-07 0.9999999999995411 1.6554784087031893
                                  children [
                                    DEF wheel Shape {
                                      appearance DamascusSteel {
                                      }
                                      geometry Cylinder {
                                        height 0.15
                                        radius 0.15
                                      }
                                    }
                                  ]
                                  boundingObject USE wheel
                                  physics Physics {
                                    mass 1
                                  }
                                  linearVelocity 4.989909156192336e-05 0.0006945989766182243 -0.0005854357329787629
                                  angularVelocity -0.00446817721233278 0.0002841944523687013 -0.00014530048801964705
                                }
                              }
                            ]
                            boundingObject USE cylinder3
                            physics DEF phy1 Physics {
                              mass 1
                            }
                          }
                        ]
                        name "solid(1)"
                        boundingObject USE sphere1
                        physics USE phy1
                      }
                    ]
                    boundingObject USE cylinder2
                    physics USE phy1
                  }
                ]
                boundingObject USE sphere1
                physics USE phy1
              }
            ]
            boundingObject USE cylinder1
            physics USE phy1
            linearVelocity 8.948846433643517e-05 0.0011990378329496518 -0.0010727835625753313
            angularVelocity -0.004468568796709252 0.00028573591770815476 -0.0001450179353333172
          }
        }
      ]
      name "wheel2_left_system"
      physics USE phy1
    }
    Solid {
      translation 0 0 0.19
      children [
        DEF body Shape {
          appearance HammeredCopper {
          }
          geometry Box {
            size 0.7 0.5 0.2
          }
        }
        Solid {
          translation 0.3 -0.19 0.15
          children [
            Shape {
              appearance Copper {
              }
              geometry Cylinder {
                height 0.1
                radius 0.02
              }
            }
          ]
          name "solar_panel_support1"
        }
        Solid {
          translation 0.3 0.19 0.15
          children [
            Shape {
              appearance Copper {
              }
              geometry Cylinder {
                height 0.1
                radius 0.02
              }
            }
          ]
          name "solar_panel_support2"
        }
        Solid {
          translation -0.3 0.19 0.14
          children [
            Shape {
              appearance Copper {
              }
              geometry Cylinder {
                height 0.1
                radius 0.02
              }
            }
          ]
          name "solar_panel_support3"
        }
        Solid {
          translation -0.3 -0.19 0.15
          children [
            Shape {
              appearance Copper {
              }
              geometry Cylinder {
                height 0.1
                radius 0.02
              }
            }
          ]
          name "solar_panel_support4"
        }
      ]
      name "solar_panel"
    }
    Solid {
      translation -0.18 -0.24 0
      children [
        SliderJoint {
          jointParameters JointParameters {
            position -5.517548690671132e-05
            minStop -0.1
            staticFriction 1
          }
          device [
            LinearMotor {
              name "linear1_left"
              maxForce 50
            }
          ]
          endPoint Solid {
            translation -0.0001828146642666173 -0.017369057338456867 0.059998272007427016
            rotation -0.9999999929253188 8.110632510218472e-05 -8.701222052623256e-05 1.5708658611060808
            children [
              DEF cylinder1 Shape {
                appearance DamascusSteel {
                }
                geometry Cylinder {
                  height 0.09
                  radius 0.02
                }
              }
              Solid {
                translation 0 0 -0.05
                children [
                  DEF sphere1 Shape {
                    appearance BrushedSteel {
                    }
                    geometry Sphere {
                      radius 0.02
                    }
                  }
                  Solid {
                    translation 0 0.1 1.79608e-07
                    rotation -1 0 0 -1.5707953071795862
                    children [
                      DEF cylinder2 Shape {
                        appearance BrushedSteel {
                        }
                        geometry Cylinder {
                          height 0.2
                          radius 0.02
                        }
                      }
                      Solid {
                        translation 0 0 -0.11
                        children [
                          DEF sphere1 Shape {
                            appearance BrushedSteel {
                            }
                            geometry Sphere {
                              radius 0.02
                            }
                          }
                          Solid {
                            translation 0 -0.03 -9.99999e-08
                            rotation 1 0 0 1.5708
                            children [
                              DEF cylinder3 Shape {
                                appearance BrushedSteel {
                                }
                                geometry Cylinder {
                                  height 0.06
                                  radius 0.02
                                }
                              }
                              HingeJoint {
                                jointParameters HingeJointParameters {
                                  position -4.627712032612473
                                  axis 0 0 1
                                  anchor -9.51224e-05 0.00113507 0.0800056
                                }
                                device [
                                  RotationalMotor {
                                    name "wheel1_left"
                                  }
                                ]
                                endPoint Solid {
                                  translation 0.001001548481052498 0.0015508740062015942 0.0800641
                                  rotation -4.815461156727558e-07 8.294840145165746e-07 0.99999999999954 1.6554771748359067
                                  children [
                                    DEF wheel Shape {
                                      appearance DamascusSteel {
                                      }
                                      geometry Cylinder {
                                        height 0.15
                                        radius 0.15
                                      }
                                    }
                                  ]
                                  boundingObject USE wheel
                                  physics Physics {
                                    mass 1
                                  }
                                  linearVelocity 1.380641515298501e-05 0.0006219276915883937 0.00039016311239534413
                                  angularVelocity -0.00446267278077135 0.00028521319919877323 -0.0001448780183917009
                                }
                              }
                            ]
                            boundingObject USE cylinder3
                            physics DEF phy1 Physics {
                              mass 1
                            }
                          }
                        ]
                        name "solid(1)"
                        boundingObject USE sphere1
                        physics USE phy1
                      }
                    ]
                    boundingObject USE cylinder2
                    physics USE phy1
                  }
                ]
                boundingObject USE sphere1
                physics USE phy1
              }
            ]
            boundingObject USE cylinder1
            physics USE phy1
            linearVelocity 5.453294340377083e-05 0.0011251480197029583 -7.66026328657978e-05
            angularVelocity -0.004462979830905095 0.00028627526353921465 -0.00014462506401049244
          }
        }
      ]
      name "wheel1_left_system"
      physics USE phy1
    }
  ]
  boundingObject DEF body Shape {
    appearance HammeredCopper {
    }
    geometry Box {
      size 0.7 0.5 0.2
    }
  }
  physics DEF phy Physics {
    mass 1
  }
  controller "sd"
  linearVelocity 0.00015098662345761028 0.001495581412612927 -0.002428955046263213
  angularVelocity -0.004465645413037695 0.0002895380211731689 -0.0001456761179453736
}
